Workbook

Sheet Summary
A1: D&Y CONSULTING — Employee Retention Confidence Interval Analysis
A2: Case Study Summary | Navigate via sheet tabs below | All CIs at 95% confidence level
A4: Analysis | B4: Group 1 — Lower | C4: Group 1 — Upper | D4: Sheet Reference
A5: Q1a: Mean Starting Salary — Stayed ≥3 Yrs | B5: ='Q1a-SalaryMeanCI'!B11 -> 36730.124 | C5: ='Q1a-SalaryMeanCI'!B12 -> 38032.376 | D5: Q1a-SalaryMeanCI
A6: Q1a: Mean Starting Salary — Left <3 Yrs | B6: ='Q1a-SalaryMeanCI'!C11 -> 37897.425 | C6: ='Q1a-SalaryMeanCI'!C12 -> 39214.339 | D6: Q1a-SalaryMeanCI
A7: Q1a: Difference in Mean Salary (Stayed−Left) | B7: ='Q1a-SalaryMeanCI'!B23 -> -2083.0954 | C7: ='Q1a-SalaryMeanCI'!B24 -> -266.16933 | D7: Q1a-SalaryMeanCI
A8: Q1b: Prop Staying — Below Median Salary | B8: ='Q1b-SalaryPropCI'!B13 -> 0.44409251 | C8: ='Q1b-SalaryPropCI'!B14 -> 0.7972868 | D8: Q1b-SalaryPropCI
A9: Q1b: Prop Staying — Above Median Salary | B9: ='Q1b-SalaryPropCI'!C13 -> 0.22210916 | C9: ='Q1b-SalaryPropCI'!C14 -> 0.5346476 | D9: Q1b-SalaryPropCI
A10: Q1b: Difference in Proportions | B10: ='Q1b-SalaryPropCI'!B24 -> 0.0065007131 | C10: ='Q1b-SalaryPropCI'!B25 -> 0.47812184 | D10: Q1b-SalaryPropCI
A11: Q2a: Mean % on Road — Stayed ≥3 Yrs | B11: ='Q2a-RoadMeanCI'!B11 -> 0.39026514 | C11: ='Q2a-RoadMeanCI'!B12 -> 0.51035986 | D11: Q2a-RoadMeanCI
A12: Q2a: Mean % on Road — Left <3 Yrs | B12: ='Q2a-RoadMeanCI'!C11 -> 0.52913843 | C12: ='Q2a-RoadMeanCI'!C12 -> 0.64439098 | D12: Q2a-RoadMeanCI
A13: Q2a: Difference in Mean Road % (Stayed−Left) | B13: ='Q2a-RoadMeanCI'!B23 -> -0.21809363 | C13: ='Q2a-RoadMeanCI'!B24 -> -0.054810786 | D13: Q2a-RoadMeanCI
A14: Q2b: Prop Staying — Low Road (≤54%) | B14: ='Q2b-RoadPropCI'!B13 -> 0.47223761 | C14: ='Q2b-RoadPropCI'!B14 -> 0.80048966 | D14: Q2b-RoadPropCI
A15: Q2b: Prop Staying — High Road (>54%) | B15: ='Q2b-RoadPropCI'!C13 -> 0.17249674 | C15: ='Q2b-RoadPropCI'!C14 -> 0.49416993 | D15: Q2b-RoadPropCI
A16: Q2b: Difference in Proportions | B16: ='Q2b-RoadPropCI'!B24 -> 0.07323526 | C16: ='Q2b-RoadPropCI'!B25 -> 0.53282535 | D16: Q2b-RoadPropCI
A17: Q3: Mean Tenure of Leavers (months) | B17: ='Q3-TenureCI'!B11 -> 12.983609 | C17: ='Q3-TenureCI'!B12 -> 17.604626 | D17: Q3-TenureCI
A18: Q4: Retention Prop — State Univ Grads | B18: ='Q4-StateUnivCI'!B10 -> 0.29301326 | C18: ='Q4-StateUnivCI'!B11 -> 0.66994971 | D18: Q4-StateUnivCI
A19: Q4: Retention Prop — Non-State Univ | B19: ='Q4-StateUnivCI'!C10 -> 0.33030837 | C19: ='Q4-StateUnivCI'!C11 -> 0.6440506 | D19: Q4-StateUnivCI
A20: Q4: Difference in Retention (SU − Non-SU) | B20: ='Q4-StateUnivCI'!B22 -> 0.23951378 | C20: ='Q4-StateUnivCI'!B23 -> 0 | D20: Q4-StateUnivCI
A22: Workbook Navigation & Color Guide
B23: Input data and intermediate calculation rows
B24: Final 95% Confidence Interval results (Lower & Upper Bounds)
B25: Interpretation and conclusion notes
B26: Explanatory notes for limitations (e.g., censored data)

Sheet RawData
A1: D&Y Consulting – Employee Retention Dataset
A2: Employee | B2: Starting Salary | C2: On Road Pct | D2: State Univ | E2: CIS Degree | F2: Stayed 3 Years | G2: Tenure
A3: 1 | B3: 38900 | C3: 0.57 | D3: Yes | E3: Yes | F3: No | G3: 11
A4: 2 | B4: 42300 | C4: 0.68 | D4: Yes | E4: Yes | F4: No | G4: 5
A5: 3 | B5: 39800 | C5: 0.75 | D5: No | E5: Yes | F5: No | G5: 21
A6: 4 | B6: 35700 | C6: 0.29 | D6: No | E6: Yes | F6: Yes
A7: 5 | B7: 40400 | C7: 0.71 | D7: No | E7: Yes | F7: No | G7: 19
A8: 6 | B8: 36400 | C8: 0.62 | D8: No | E8: Yes | F8: No | G8: 18
A9: 7 | B9: 37300 | C9: 0.41 | D9: Yes | E9: No | F9: Yes
A10: 8 | B10: 36600 | C10: 0.37 | D10: No | E10: Yes | F10: No | G10: 17
A11: 9 | B11: 34600 | C11: 0.65 | D11: No | E11: Yes | F11: No | G11: 20
A12: 10 | B12: 42300 | C12: 0.53 | D12: Yes | E12: Yes | F12: No | G12: 16
A13: 11 | B13: 37800 | C13: 0.73 | D13: No | E13: Yes | F13: Yes
A14: 12 | B14: 39700 | C14: 0.6 | D14: No | E14: Yes | F14: No | G14: 12
A15: 13 | B15: 36100 | C15: 0.56 | D15: Yes | E15: Yes | F15: Yes
A16: 14 | B16: 36100 | C16: 0.42 | D16: Yes | E16: Yes | F16: Yes
A17: 15 | B17: 33800 | C17: 0.35 | D17: No | E17: Yes | F17: Yes
A18: 16 | B18: 38900 | C18: 0.36 | D18: No | E18: Yes | F18: Yes
A19: 17 | B19: 35500 | C19: 0.5 | D19: No | E19: Yes | F19: No | G19: 15
A20: 18 | B20: 37600 | C20: 0.58 | D20: No | E20: Yes | F20: Yes
A21: 19 | B21: 38100 | C21: 0.78 | D21: Yes | E21: Yes | F21: Yes
A22: 20 | B22: 38300 | C22: 0.16 | D22: No | E22: No | F22: Yes
A23: 21 | B23: 34600 | C23: 0.29 | D23: No | E23: Yes | F23: Yes
A24: 22 | B24: 36300 | C24: 0.26 | D24: No | E24: Yes | F24: Yes
A25: 23 | B25: 37200 | C25: 0.59 | D25: Yes | E25: Yes | F25: No | G25: 14
A26: 24 | B26: 37700 | C26: 0.55 | D26: Yes | E26: Yes | F26: Yes
A27: 25 | B27: 36600 | C27: 0.45 | D27: No | E27: Yes | F27: No | G27: 13
A28: 26 | B28: 41000 | C28: 0.81 | D28: Yes | E28: Yes | F28: No | G28: 9
A29: 27 | B29: 40800 | C29: 1.11 | D29: Yes | E29: Yes | F29: No | G29: 7
A30: 28 | B30: 36700 | C30: 0.56 | D30: Yes | E30: Yes | F30: Yes
A31: 29 | B31: 37700 | C31: 0.56 | D31: No | E31: Yes | F31: No | G31: 22
A32: 30 | B32: 37700 | C32: 0.42 | D32: No | E32: Yes | F32: No | G32: 11
A33: 31 | B33: 39300 | C33: 0.69 | D33: Yes | E33: Yes | F33: No | G33: 16
A34: 32 | B34: 37500 | C34: 0.5 | D34: No | E34: Yes | F34: No | G34: 18
A35: 33 | B35: 40000 | C35: 0.69 | D35: Yes | E35: Yes | F35: No | G35: 9
A36: 34 | B36: 41500 | C36: 0.64 | D36: Yes | E36: No | F36: No | G36: 5
A37: 35 | B37: 39600 | C37: 0.72 | D37: No | E37: Yes | F37: No | G37: 18
A38: 36 | B38: 36900 | C38: 0.42 | D38: No | E38: Yes | F38: Yes
A39: 37 | B39: 39500 | C39: 0.62 | D39: No | E39: Yes | F39: No | G39: 5
A40: 38 | B40: 37800 | C40: 0.2 | D40: No | E40: Yes | F40: No | G40: 23
...

Sheet Q1a-SalaryMeanCI
A1: Q1(a): 95% Confidence Intervals — Mean Starting Salary by Retention Group
A3: Statistic | B3: Stayed ≥ 3 Years | C3: Left < 3 Years | D3: All Employees
A4: Sample Size (n) | B4: =COUNTIF(RawData!F3:F68,"Yes") -> 32 | C4: =COUNTIF(RawData!F3:F68,"No") -> 34 | D4: =COUNT(RawData!B3:B68) -> 66
A5: Sample Mean | B5: =AVERAGEIF(RawData!F3:F68,"Yes",RawData!B3:B68) -> 37381.25 | C5: =AVERAGEIF(RawData!F3:F68,"No",RawData!B3:B68) -> 38555.882 | D5: =AVERAGE(RawData!B3:B68) -> 37986.364
A6: Sample Std Dev | B6: =SQRT((SUMPRODUCT((RawData!F3:F68="Yes")*RawData!B3:B68^2)-SUMPRODUCT((RawData!F3:F68="Yes")*RawData!B3:B68)^2/COUNTIF(RawData!F3:F68,"Yes"))/(COUNTIF(RawData!F3:F68,"Yes")-1)) -> 1805.9824 | C6: =SQRT((SUMPRODUCT((RawData!F3:F68="No")*RawData!B3:B68^2)-SUMPRODUCT((RawData!F3:F68="No")*RawData!B3:B68)^2/COUNTIF(RawData!F3:F68,"No"))/(COUNTIF(RawData!F3:F68,"No")-1)) -> 1887.1481 | D6: =STDEV(RawData!B3:B68) -> 1927.0453
A7: Std Error (s/√n) | B7: =B6/SQRT(B4) -> 319.25561 | C7: =C6/SQRT(C4) -> 323.64323 | D7: =D6/SQRT(D4) -> 237.20288
A8: Degrees of Freedom (n-1) | B8: =B4-1 -> 31 | C8: =C4-1 -> 33 | D8: =D4-1 -> 65
A9: t* Critical Value (95%) | B9: =TINV(0.05,B8) -> 2.0395134 | C9: =TINV(0.05,C8) -> 2.0345153 | D9: =TINV(0.05,D8) -> 1.9971379
A10: Margin of Error | B10: =B9*B7 -> 651.12611 | C10: =C9*C7 -> 658.4571 | D10: =D9*D7 -> 473.72686
A11: 95% CI — Lower Bound ✦ | B11: =B5-B10 -> 36730.124 | C11: =C5-C10 -> 37897.425 | D11: =D5-D10 -> 37512.637
A12: 95% CI — Upper Bound ✦ | B12: =B5+B10 -> 38032.376 | C12: =C5+C10 -> 39214.339 | D12: =D5+D10 -> 38460.09
A13: ✦ = Key result rows. Std Dev uses SUMPRODUCT-based conditional formula (no array entry needed).
A15: 95% CI for Difference in Means (Stayed − Left)
A16: Mean (Stayed) | B16: =B5 -> 37381.25
A17: Mean (Left) | B17: =C5 -> 38555.882
A18: Point Estimate (Diff = Stayed − Left) | B18: =B16-B17 -> -1174.6324
A19: SE of Difference (Welch) | B19: =SQRT(B6^2/B4+C6^2/C4) -> 454.60872
A20: Welch df | B20: =(B6^2/B4+C6^2/C4)^2/((B6^2/B4)^2/(B4-1)+(C6^2/C4)^2/(C4-1)) -> 63.98016
A21: t* (95%, Welch df) | B21: =TINV(0.05,B20) -> 1.9983405
A22: Margin of Error | B22: =B21*B19 -> 908.46303
A23: 95% CI — Lower Bound ✦ | B23: =B18-B22 -> -2083.0954
A24: 95% CI — Upper Bound ✦ | B24: =B18+B22 -> -266.16933
A26: 📊 INTERPRETATION — Q1(a): The two CIs for mean starting salary show the range within which the true mean salary lies for each group (95% confidence). If the CI for the difference (Stayed − Left) contains 0, starting salary is NOT a statistically significant predictor of retention. Substantial overlap of the individual group CIs also suggests minimal salary impact on staying.

Sheet Q1b-SalaryPropCI
A1: Q1(b): 95% CI for Proportion Staying ≥ 3 Years — by Starting Salary vs. Median
A3: Median Reference
A4: Median used (given in case) | B4: 37500 | C4: Case states median = $37,500
A6: Statistic | B6: Below Median ($≤37,500) | C6: Above Median ($>37,500)
A7: Total in group (n) | B7: =COUNTIF(RawData!B3:B68,"<="&B4) -> 29 | C7: =COUNTIF(RawData!B3:B68,">"&B4) -> 37
A8: Stayed ≥ 3 Years (x) | B8: =SUMPRODUCT((RawData!B3:B68<=B4)*(RawData!F3:F68="Yes")) -> 18 | C8: =SUMPRODUCT((RawData!B3:B68>B4)*(RawData!F3:F68="Yes")) -> 14
A9: Sample Proportion p̂ = x/n | B9: =B8/B7 -> 0.62068966 | C9: =C8/C7 -> 0.37837838
A10: SE = √(p̂(1−p̂)/n) | B10: =SQRT(B9*(1-B9)/B7) -> 0.090102242 | C10: =SQRT(C9*(1-C9)/C7) -> 0.079730658
A11: z* Critical Value (95%) | B11: =NORMINV(0.975,0,1) -> 1.959964 | C11: =NORMINV(0.975,0,1) -> 1.959964
A12: Margin of Error | B12: =B11*B10 -> 0.17659715 | C12: =C11*C10 -> 0.15626922
A13: 95% CI — Lower Bound ✦ | B13: =B9-B12 -> 0.44409251 | C13: =C9-C12 -> 0.22210916
A14: 95% CI — Upper Bound ✦ | B14: =B9+B12 -> 0.7972868 | C14: =C9+C12 -> 0.5346476
A17: 95% CI for Difference in Proportions (Group 1 − Group 2)
A18: p̂ Group 1 | B18: =B9 -> 0.62068966
A19: p̂ Group 2 | B19: =C9 -> 0.37837838
A20: Point Estimate (diff) | B20: =B18-B19 -> 0.24231128
A21: SE of Difference | B21: =SQRT(B10^2+C10^2) -> 0.12031372
A22: z* (95%) | B22: =NORMINV(0.975,0,1) -> 1.959964
A23: Margin of Error | B23: =B22*B21 -> 0.23581056
A24: 95% CI — Lower Bound ✦ | B24: =B20-B23 -> 0.0065007131
A25: 95% CI — Upper Bound ✦ | B25: =B20+B23 -> 0.47812184
A27: 📊 INTERPRETATION — Q1(b): Compare retention rates between employees earning above vs. below the median starting salary. If the 95% CI for the difference contains 0, salary level relative to the median does not significantly affect the likelihood of staying ≥ 3 years at D&Y.

Sheet Q2a-RoadMeanCI
A1: Q2(a): 95% Confidence Intervals — Mean % Time on Road by Retention Group
A3: Statistic | B3: Stayed ≥ 3 Years | C3: Left < 3 Years | D3: All Employees
A4: Sample Size (n) | B4: =COUNTIF(RawData!F3:F68,"Yes") -> 32 | C4: =COUNTIF(RawData!F3:F68,"No") -> 34 | D4: =COUNT(RawData!C3:C68) -> 66
A5: Sample Mean | B5: =AVERAGEIF(RawData!F3:F68,"Yes",RawData!C3:C68) -> 0.4503125 | C5: =AVERAGEIF(RawData!F3:F68,"No",RawData!C3:C68) -> 0.58676471 | D5: =AVERAGE(RawData!C3:C68) -> 0.52060606
A6: Sample Std Dev | B6: =SQRT((SUMPRODUCT((RawData!F3:F68="Yes")*RawData!C3:C68^2)-SUMPRODUCT((RawData!F3:F68="Yes")*RawData!C3:C68)^2/COUNTIF(RawData!F3:F68,"Yes"))/(COUNTIF(RawData!F3:F68,"Yes")-1)) -> 0.16654912 | C6: =SQRT((SUMPRODUCT((RawData!F3:F68="No")*RawData!C3:C68^2)-SUMPRODUCT((RawData!F3:F68="No")*RawData!C3:C68)^2/COUNTIF(RawData!F3:F68,"No"))/(COUNTIF(RawData!F3:F68,"No")-1)) -> 0.16515779 | D6: =STDEV(RawData!C3:C68) -> 0.1783245
A7: Std Error (s/√n) | B7: =B6/SQRT(B4) -> 0.029442003 | C7: =C6/SQRT(C4) -> 0.028324327 | D7: =D6/SQRT(D4) -> 0.021950228
A8: Degrees of Freedom (n-1) | B8: =B4-1 -> 31 | C8: =C4-1 -> 33 | D8: =D4-1 -> 65
A9: t* Critical Value (95%) | B9: =TINV(0.05,B8) -> 2.0395134 | C9: =TINV(0.05,C8) -> 2.0345153 | D9: =TINV(0.05,D8) -> 1.9971379
A10: Margin of Error | B10: =B9*B7 -> 0.060047361 | C10: =C9*C7 -> 0.057626276 | D10: =D9*D7 -> 0.043837633
A11: 95% CI — Lower Bound ✦ | B11: =B5-B10 -> 0.39026514 | C11: =C5-C10 -> 0.52913843 | D11: =D5-D10 -> 0.47676843
A12: 95% CI — Upper Bound ✦ | B12: =B5+B10 -> 0.51035986 | C12: =C5+C10 -> 0.64439098 | D12: =D5+D10 -> 0.56444369
A13: ✦ = Key result rows. Std Dev uses SUMPRODUCT-based conditional formula (no array entry needed).
A15: 95% CI for Difference in Means (Stayed − Left)
A16: Mean (Stayed) | B16: =B5 -> 0.4503125
A17: Mean (Left) | B17: =C5 -> 0.58676471
A18: Point Estimate (Diff = Stayed − Left) | B18: =B16-B17 -> -0.13645221
A19: SE of Difference (Welch) | B19: =SQRT(B6^2/B4+C6^2/C4) -> 0.040854608
A20: Welch df | B20: =(B6^2/B4+C6^2/C4)^2/((B6^2/B4)^2/(B4-1)+(C6^2/C4)^2/(C4-1)) -> 63.688229
A21: t* (95%, Welch df) | B21: =TINV(0.05,B20) -> 1.9983405
A22: Margin of Error | B22: =B21*B19 -> 0.08164142
A23: 95% CI — Lower Bound ✦ | B23: =B18-B22 -> -0.21809363
A24: 95% CI — Upper Bound ✦ | B24: =B18+B22 -> -0.054810786
A26: 📊 INTERPRETATION — Q2(a): Employees who leave tend to have a higher % of time on the road. If the CI for the difference (Stayed − Left) is entirely below 0, those who stay spent significantly less time on the road — suggesting travel burden is a key driver of attrition.

Sheet Q2b-RoadPropCI
A1: Q2(b): 95% CI for Proportion Staying ≥ 3 Years — by % on Road vs. Median (54%)
A3: Median Reference
A4: Median used (given in case) | B4: 0.54 | C4: Case states median = 54%
A6: Statistic | B6: Low Road (≤54%) | C6: High Road (>54%)
A7: Total in group (n) | B7: =COUNTIF(RawData!C3:C68,"<="&B4) -> 33 | C7: =COUNTIF(RawData!C3:C68,">"&B4) -> 33
A8: Stayed ≥ 3 Years (x) | B8: =SUMPRODUCT((RawData!C3:C68<=B4)*(RawData!F3:F68="Yes")) -> 21 | C8: =SUMPRODUCT((RawData!C3:C68>B4)*(RawData!F3:F68="Yes")) -> 11
A9: Sample Proportion p̂ = x/n | B9: =B8/B7 -> 0.63636364 | C9: =C8/C7 -> 0.33333333
A10: SE = √(p̂(1−p̂)/n) | B10: =SQRT(B9*(1-B9)/B7) -> 0.083739307 | C10: =SQRT(C9*(1-C9)/C7) -> 0.082060994
A11: z* Critical Value (95%) | B11: =NORMINV(0.975,0,1) -> 1.959964 | C11: =NORMINV(0.975,0,1) -> 1.959964
A12: Margin of Error | B12: =B11*B10 -> 0.16412603 | C12: =C11*C10 -> 0.16083659
A13: 95% CI — Lower Bound ✦ | B13: =B9-B12 -> 0.47223761 | C13: =C9-C12 -> 0.17249674
A14: 95% CI — Upper Bound ✦ | B14: =B9+B12 -> 0.80048966 | C14: =C9+C12 -> 0.49416993
A17: 95% CI for Difference in Proportions (Group 1 − Group 2)
A18: p̂ Group 1 | B18: =B9 -> 0.63636364
A19: p̂ Group 2 | B19: =C9 -> 0.33333333
A20: Point Estimate (diff) | B20: =B18-B19 -> 0.3030303
A21: SE of Difference | B21: =SQRT(B10^2+C10^2) -> 0.11724452
A22: z* (95%) | B22: =NORMINV(0.975,0,1) -> 1.959964
A23: Margin of Error | B23: =B22*B21 -> 0.22979504
A24: 95% CI — Lower Bound ✦ | B24: =B20-B23 -> 0.07323526
A25: 95% CI — Upper Bound ✦ | B25: =B20+B23 -> 0.53282535
A27: 📊 INTERPRETATION — Q2(b): If the low-road group has a significantly higher retention rate, travel burden is confirmed as a retention risk. A CI for the difference that excludes 0 (and is positive) means low-road employees are statistically more likely to stay ≥ 3 years.

Sheet Q3-TenureCI
A1: Q3: 95% CI for Mean Tenure (months) — Employees Who Left within 3 Years
A3: Statistic | B3: Value
A4: n (employees who left — have Tenure recorded) | B4: =COUNT(RawData!G3:G68) -> 34
A5: Sample Mean Tenure (months) | B5: =AVERAGE(IF(RawData!F3:F68="No",RawData!G3:G68)) -> 15.294118
A6: Sample Std Dev of Tenure | B6: =SQRT((SUMPRODUCT((RawData!F3:F68="No")*RawData!G3:G68^2)-SUMPRODUCT((RawData!F3:F68="No")*RawData!G3:G68)^2/COUNTIF(RawData!F3:F68,"No"))/(COUNTIF(RawData!F3:F68,"No")-1)) -> 6.6219534
A7: Std Error (SE = s/√n) | B7: =B6/SQRT(B4) -> 1.1356556
A8: Degrees of Freedom (n-1) | B8: =B4-1 -> 33
A9: t* Critical Value (95%, two-tail) | B9: =TINV(0.05,B8) -> 2.0345153
A10: Margin of Error (months) | B10: =B9*B7 -> 2.3105088
A11: 95% CI — Lower Bound ✦ (months) | B11: =B5-B10 -> 12.983609
A12: 95% CI — Upper Bound ✦ (months) | B12: =B5+B10 -> 17.604626
A14: * Mean Tenure uses AVERAGE(IF()) — enter as array formula (Ctrl+Shift+Enter) if needed.
A16: Why No CI for ALL Employees (Including Those Still at D&Y)?
A17: Employees who stayed ≥ 3 years have NO Tenure value recorded — their employment is ongoing and their final tenure is unknown (right-censored data). A standard confidence interval for the mean requires complete, observed values for all units. Since we cannot observe when (or if) current employees will eventually leave, we cannot calculate a valid CI for mean tenure across ALL D&Y employees. Advanced survival analysis (e.g., Kaplan-Meier) would be required to handle censored observations.

Sheet Q4-StateUnivCI
A1: Q4: Are State University CIS Graduates Harder to Retain? — Proportion CI Analysis
A3: Statistic | B3: State Univ Grads | C3: Non-State Univ
A4: Total in group | B4: =COUNTIF(RawData!D3:D68,"Yes") -> 27 | C4: =COUNTIF(RawData!D3:D68,"No") -> 39
A5: Number who stayed ≥ 3 years | B5: =SUMPRODUCT((RawData!D3:D68="Yes")*(RawData!F3:F68="Yes")) -> 13 | C5: =SUMPRODUCT((RawData!D3:D68="No")*(RawData!F3:F68="Yes")) -> 19
A6: Sample Proportion p̂ who stayed | B6: =B5/B4 -> 0.48148148 | C6: =C5/C4 -> 0.48717949
A7: SE = √(p̂(1−p̂)/n) | B7: =SQRT(B6*(1-B6)/B4) -> 0.096159024 | C7: =SQRT(C6*(1-C6)/C4) -> 0.080037753
A8: z* Critical Value (95%) | B8: =NORMINV(0.975,0,1) -> 1.959964 | C8: =NORMINV(0.975,0,1) -> 1.959964
A9: Margin of Error | B9: =B8*B7 -> 0.18846822 | C9: =C8*C7 -> 0.15687111
A10: 95% CI — Lower Bound ✦ | B10: =B6-B9 -> 0.29301326 | C10: =C6-C9 -> 0.33030837
A11: 95% CI — Upper Bound ✦ | B11: =B6+B9 -> 0.66994971 | C11: =C6+C9 -> 0.6440506
A14: 95% CI for Difference in Retention (State Univ − Non-State Univ)
A15: p̂ State University Graduates | B15: =B6 -> 0.48148148
A16: p̂ Non-State University | B16: =C6 -> 0.48717949
A17: Point Estimate (diff) | B17: =B15-B16 -> -0.0056980057
A18: SE of Difference | B18: =SQRT(B7^2+C7^2) -> 0.12511035
A19: z* (95%) | B19: =NORMINV(0.975,0,1) -> 1.959964
A20: Margin of Error | B20: =B19*B18 -> 0.24521178
A21: 95% CI — Lower Bound ✦ | B21: =B17-B20 -> -0.25090979
A22: 95% CI — Upper Bound ✦ | B22: =B17+B20 -> 0.23951378
A24: 📊 INTERPRETATION — Q4: If the CI for the difference (State Univ − Non-State Univ) is entirely BELOW 0, State Univ graduates have a significantly LOWER retention rate — they ARE harder to retain. If the CI contains 0, there is no statistically significant difference in retention between the two groups. Check CIS-specific graduates using the CIS Degree filter for deeper insight.
